File: data/references/Iron_references.vms
VAMAS Surface Chemical Analysis Standard Data Transfer Format 1988 May 4
Not Specified
Not Specified
Not Specified
Not Specified
12
Casa Info Follows CasaXPS Version 2.3.23rev1.0Y
0
Created by SpecsLab Prodigy, Version 4.54.1-r81613
SourceAnalyserAngle: Not Specified
CasaRowLabel:Fe metal
CasaRowLabel:FeO
CasaRowLabel:Fe3O4
CasaRowLabel:Fe2O3
CasaRowLabel:Fe metal unscattered
CasaRowLabel:FeO unscattered
CasaRowLabel:Fe3O4 unscattered
CasaRowLabel:Fe2O3 unscattered
NORM
REGULAR
10
1
Exp Variable
d
0
0
0
0
43
Survey
Fe metal
2019
10
11
1
45
12
0
16
Casa Info Follows
0
0
0
0
File = C:/Users/pielsticker/Lukas/MPI-CEC/Projects/Ammonia Synthesis/Data/NAP-XPS/EX232_CEC427_Fe2O3_labREF.sle
Group = 33 Ramp down in H2, #Treatments:, #Temp: 600 C , #Pressure: 0.5 mbar, #Gas1: H2, #Gas2:, #Gas Ratio:, #Comments:
First of group = 1
Analyzer lens = AngleResolvedMode22:1.5kV
Analyzer slit = 4:7x20c\C:mesh
Scan mode = FixedAnalyzerTransmission
Kinetic energy start = 386.61
c:\users\pielsticker\lukas\mpi-cec\projects\ammonia synthesis\data\nap-xps\raw data\ex232_cec427_fe2o3_labref.vms
C:\Users\pielsticker\SIALab\Project data\Ammonia Synthesis\Data\NAP-XPS\analyzed data\Iron references\Fe metal.vms
C:\Users\pielsticker\Lukas\MPI-CEC\Projects\Ammonia Synthesis\Data\NAP-XPS\analyzed data\Iron references\Fe_metal.vms
C:\Users\pielsticker\Lukas\MPI-CEC\Projects\Ammonia Synthesis\Data\NAP-XPS\analyzed data\Iron references\Iron_references.vms
XPS
0
Al
1486.61
0
0
0
54.5
180
FAT
20
1
4.3058
0
0
0
0
0
Survey

-1
kinetic energy
eV
386.61
1
2
counts
d
Transmission
d
pulse counting
0.1
1
0
0
0
0
2
ESCAPE DEPTH TYPE
d
1
MFP Exponent
d
0
13.9622
1.94945
696.631
683.552
707.638
722.075
703.809
734.606
710.939
723.612
713.708
702.517
704.718
672.915
702.481
700.351
702.659
726.096
715.134
718.699
710.528
721.223
744.022
772.513
711.411
734.021
734.561
685.532
685.498
746.444
699.688
713.454
744.502
766.473
756.627
710.552
710.89
743.446
726.992
747.392
750.04
745.199
726.766
736.165
734.561
722.171
800.422
764.081
750.98
750.368
756.209
757.602
762.275
753.063
781.814
774.974
775.408
777.765
782.821
781.455
779.013
808.046
790.175
803.717
805.88
786.672
839.717
848.986
780.071
799.202
814.246
825.487
841.308
816.153
768.257
808.468
849.034
855.828
786.029
805.954
830.953
837.376
885.785
828.121
780.452
822.176
844.219
830.192
819.847
862.653
852.065
830.329
843.311
866.84
843.937
824.478
816.287
862.339
879.238
876.6
860.93
883.714
878.879
863.366
881.922
864.155
928.356
880.184
911.877
903.488
881.82
911.777
933.808
922.438
915.497
890.651
921.365
913.848
886.345
924.881
941.726
891.173
907.443
905.76
942.062
967.517
957.921
932.358
960.629
948.112
982.89
983.038
958.93
941.658
919.312
909.38
920.463
959.879
960.879
935.174
949.677
907.48
965.63
969.562
967.748
977.882
978.671
966.179
948.768
944.378
902.967
925.786
975.843
958.47
961.826
983.007
967.739
949.03
962.464
972.988
967.788
980.489
994.513
1031.14
979.451
1055.5
1056.55
1073.13
1042.38
1042.7
1027.88
1031.8
1025.4
1030.4
1063.77
1022.79
1011.03
1065.99
1113.74
1061.46
1054.99
1103.66
1048.49
993.438
1041.92
1055.36
1027.74
1041.07
1072.19
1011.96
1040.27
1091.33
1107.39
1071.45
1102.38
1126.22
1123.33
1112.34
1111.85
1147.46
1127.68
1110.72
1114.97
1116.33
1091.6
1160.46
1147.65
1150.17
1150.25
1096.08
1104.07
1120.03
1128.84
1163.28
1175.23
1137.42
1063.38
991.826
937.949
942.192
877.676
909.671
925.238
909.217
898.315
928.706
942.618
946.43
947.668
926.566
918.398
934.808
905.707
941.519
918.609
875.641
922.689
955.761
916.644
961.03
919.948
922.545
932.321
919.87
925.751
952.702
990.06
996.106
990.7
970.93
962.203
984.626
1023.42
1054.18
1070.51
1109.66
1074.28
1135.58
1115.31
1096.29
1103.14
1089.85
1054.41
1073.8
1034.79
1019.25
1009.47
981.328
944.723
885.342
810.954
700.877
694.153
685.794
676.073
645.01
681.746
648.171
647.404
638.069
638.806
631.493
667.284
653.392
639.361
663.81
679.272
643.673
634.928
673.116
639.837
650.633
649.074
692.625
697.108
658.314
678.819
690.293
681.37
668.336
679.464
673.325
702.637
702.408
700.041
663.607
715.334
687.52
665.523
710.452
713.424
719.122
714.014
743.945
778.78
781.395
858.402
916.667
935.872
957.929
902.563
829.589
745.695
702.994
652.45
628.65
684.53
644.747
638.478
633.017
654.138
626.039
644.259
646.322
626.267
662.059
632.131
620.465
593.976
609.842
609.414
609.317
595.458
595.803
631.766
656.01
630.32
614.644
631.784
640.099
638.81
698.994
721.284
700.254
723.625
685.891
687.36
685.01
717.388
739.746
721.089
734.133
785.772
794.144
751.021
775.023
761.913
743.58
755.638
789.083
826.965
811.169
836.432
826.252
812.795
811.639
830.446
869.565
888.574
894.419
978.458
1210.49
1336.22
1110.1
758.883
677.463
646.502
633.028
620.848
632.37
670.554
743.485
827.87
956.569
1413.37
1926.96
1044.92
251.974
104.848
83.086
75.1211
70.2092
70.9841
56.9731
71.0769
65.9963
77.0566
62.422
73.2295
71.0663
60.877
49.5894
55.1208
55.5796
58.7686
73.2234
65.2509
67.8091
59.1788
72.5179
72.8554
69.9617
69.3126
72.285
65.6176
55.9318
56.3839
58.032
54.7259
58.8731
67.8028
61.5359
62.3734
69.6759
64.0461
55.4984
62.6663
62.7771
70.3844
70.8218
60.5633
57.2465
69.8731
74.3708
75.0216
69.4189
63.0069
72.7373
67.489
67.6758
65.1286
69.6367
63.7955
64.7123
62.0781
59.8979
58.188
78.0075
71.5483
55.59
64.0713
69.3833
65.7901
62.8612
67.1203
67.3899
82.6959
68.2676
66.2496
61.7341
75.5815
61.4366
63.7139
63.1923
59.8191
65.268
73.781
68.3589
67.1862
67.6399
82.9446
86.8924
67.082
72.8818
72.2547
67.3694
77.7389
72.0888
66.7137
68.7885
73.5966
73.1682
66.0031
70.8661
68.6796
59.2871
70.3936
69.5667
77.4516
74.9529
80.4063
66.3509
69.8094
67.063
71.8327
77.9185
70.5874
81.7455
69.4878
65.9652
63.9321
67.9977
78.993
72.2344
73.9834
64.0323
66.2018
82.8271
78.3541
80.5284
84.064
74.3401
73.0731
72.7269
82.0765
87.2653
60.0998
74.8914
88.192
70.5554
71.0736
89.2812
64.0504
63.2481
70.5276
66.4408
69.7339
74.0151
85.3563
92.7809
83.7345
73.8087
95.2346
94.8387
70.7577
70.9734
77.331
78.2018
79.748
77.7052
79.4401
76.1717
90.9421
80.9194
80.5904
85.6356
80.4526
77.9972
81.9683
89.349
83.9511
81.3823
93.8039
82.6664
84.4445
78.9549
76.4645
85.6679
97.943
114.451
131.744
166.831
173.936
117.244
85.9901
80.9905
72.7792
72.3207
71.1083
64.7713
65.774
65.3282
65.2968
76.2285
67.0894
75.954
70.3624
61.2778
58.6918
78.9278
67.8397
72.6618
71.938
72.7414
78.126
78.2573
74.6435
82.3674
64.7143
78.8966
84.4268
86.0787
80.6808
76.2839
65.516
92.4158
82.8409
84.9059
87.7836
75.0884
74.8118
70.1972
77.0187
65.0611
87.5919
82.6111
73.9669
78.7893
60.704
68.8979
68.9213
72.7283
80.2254
81.5133
82.1799
64.4212
85.6454
83.5518
66.6453
75.7423
77.6094
72.1753
68.2652
62.1124
80.4395
74.1981
75.9429
76.0117
85.1339
79.5484
82.8441
87.7792
78.5303
89.9632
92.6756
74.8565
72.0481
79.3062
83.3022
74.1783
76.0674
71.8076
80.7718
84.1155
82.4729
84.5965
85.0005
79.1242
73.9531
65.162
70.4171
72.3446
86.6166
76.3658
80.0854
80.7748
68.3153
75.4846
73.9223
75.2517
81.0271
73.6277
86.215
80.6675
73.8632
76.7385
76.022
79.918
83.4455
84.9757
81.591
75.0417
75.423
71.7683
86.2789
73.3525
84.2661
77.1325
75.5658
84.964
82.7293
72.4263
84.8322
79.1897
74.1937
80.959
88.6984
74.5961
91.3345
92.8494
84.6865
80.4538
76.9223
90.1677
79.1262
71.9348
70.2229
76.0509
67.6361
70.8264
88.2439
94.2776
89.6651
90.2853
82.7079
90.0189
72.5612
86.7823
89.7779
87.0406
87.81
73.4532
77.0714
85.3257
79.4608
75.1442
89.6861
89.1747
76.4139
81.2379
85.8133
92.9559
73.9422
67.1717
87.4577
77.6442
85.9485
82.2169
85.8629
92.987
91.4737
77.682
84.7317
88.905
92.0747
100.44
82.1355
74.6714
77.5346
86.7453
90.4386
87.263
91.1784
84.988
84.7611
89.3156
87.0098
78.714
79.9089
89.6766
75.0108
86.2026
86.7294
77.5699
82.1859
84.3871
71.1239
68.4132
86.4356
89.7108
77.0525
75.4042
83.2855
96.3
90.4089
86.5653
81.0885
82.3041
91.6989
90.1564
93.3909
82.022
81.5767
88.0979
90.7695
79.0672
76.9515
77.8035
79.7798
101.53
99.6597
78.9448
86.4022
94.3721
96.5259
86.3495
83.6018
89.0782
84.1486
94.4994
92.9727
81.7395
91.9622
81.7867
91.129
82.4349
98.0953
90.5612
83.9086
89.5384
101.584
87.8407
91.5279
81.5659
77.9888
78.8963
88.7854
92.9947
80.9065
94.6291
96.5219
92.4843
82.3806
73.4014
78.4444
86.8848
81.6932
87.7678
89.0637
90.133
97.3705
93.3746
100.012
90.6017
85.849
90.2307
98.2209
93.2754
89.8384
97.6374
96.1967
95.9484
90.6794
90.9557
89.5762
96.0993
96.2878
94.8753
87.9215
100.468
96.7168
90.2836
75.8199
77.8581
84.8523
85.6737
95.0661
96.3786
100.795
113.756
99.4163
91.4028
104.094
107.779
96.0903
93.0372
108.817
97.9065
88.7872
109.882
106.097
87.1455
106.198
106.997
100.268
92.0178
92.7467
102.763
112.824
105.469
87.9961
109.506
96.1232
88.1388
112.871
96.3656
99.0299
94.7957
116.219
103.895
100.275
112.218
109.687
101.045
96.3968
96.4094
112.488
100.745
97.337
101.352
99.2637
113.91
93.0077
101.808
109.401
109.252
121.698
110.264
118.206
102.633
109.067
94.7108
94.9983
108.933
108.192
115.553
123.795
101.263
108.876
110.78
100.088
102.89
105.711
104.508
119.18
118.174
104.382
114.929
101.159
116.036
99.7474
122.569
124.398
96.3506
105.328
110.506
116.831
114.637
103.717
124.582
132.106
123.383
118.003
116.148
112.173
98.9066
116.19
117.323
113.678
103.779
107.031
111.504
109.163
116.24
117.369
116.716
124.887
113.706
126.25
119.927
116.269
123.737
132.843
119.454
123.928
126.933
131.701
119.482
132.922
133.71
121.601
111.008
115.983
114.909
126.235
110.464
119.095
125.166
127.706
120.068
121.182
136.15
126.606
128.875
135.262
137.079
140.73
136.296
130.252
131.394
114.412
127.085
138.987
129.101
132.886
125.312
116.542
130.061
124.183
135.842
130.126
145.863
135.068
158.575
167.966
175.427
177.061
176.117
182.35
189.755
226.161
236.676
209.255
132.813
132.363
126.316
124.354
117.75
122.068
122.022
108.506
121.056
127.165
125.412
133.971
139.881
148.68
144.259
137.118
138.034
139.156
120.176
130.646
128.232
121.723
133.985
139.275
122.108
120.142
113.814
117.921
135.012
138.973
123.444
134.305
165.864
179.693
210.103
285.057
388.86
276.845
90.9336
43.5291
26.0296
21.5778
20.761
13.9622
17.7696
18.3586
18.0897
22.3346
16.0113
16.0939
15.8959
15.1986
16.114
24.3529
28.2643
23.7852
18.9116
20.9594
23.1417
27.5436
23.2042
21.5917
15.7467
17.3817
22.5639
23.5357
18.9276
18.2795
23.1618
16.9821
21.6624
20.2601
17.6662
24.0945
19.6977
20.0071
22.0933
21.0909
20.6519
18.5429
22.3722
28.7465
26.6446
30.7035
30.1341
36.7062
48.875
63.1905
70.8301
55.6234
1.94945
Fe2p
Fe metal
2019
10
11
2
0
34
0
19
Casa Info Follows
0
0
0
0
File = C:/Users/pielsticker/Lukas/MPI-CEC/Projects/Ammonia Synthesis/Data/NAP-XPS/EX232_CEC427_Fe2O3_labREF.sle
Group = 33 Ramp down in H2, #Treatments:, #Temp: 600 C , #Pressure: 0.5 mbar, #Gas1: H2, #Gas2:, #Gas Ratio:, #Comments:
First of group = 0
Analyzer lens = AngleResolvedMode22:1.5kV
Analyzer slit = 4:7x20c\C:mesh
Scan mode = FixedAnalyzerTransmission
Kinetic energy start = 736.61
c:\users\pielsticker\lukas\mpi-cec\projects\ammonia synthesis\data\nap-xps\raw data\ex232_cec427_fe2o3_labref.vms
c:\users\pielsticker\lukas\mpi-cec\projects\datascience\machinelearning\iron references\fe metal_analyzed.vms
C:\Users\pielsticker\SIALab\Project data\Ammonia Synthesis\Data\NAP-XPS\analyzed data\Iron references\Fe metal_analyzed.vms
CasaXP2
c:\users\pielsticker\lukas\mpi-cec\projects\ammonia synthesis\data\nap-xps\analyzed data\iron references\fe_metal_analyzed.vms
CasaXP3
C:\Users\pielsticker\Lukas\MPI-CEC\Projects\Ammonia Synthesis\Data\NAP-XPS\analyzed data\Iron references\Iron_references.vms
XPS
0
Al
1486.61
0
0
0
54.5
180
FAT
20
1
4.3058
0
0
0
0
0
Fe
2p
-1
kinetic energy
eV
736.61
0.05
2
counts
d
Transmission
d
pulse counting
0.2
3
0
0
0
0
3
PROPAGATION_CONVERGED
d
1
ESCAPE DEPTH TYPE
d
1
MFP Exponent
d
0
359.235
2.67321
4091.32
4036.37
3963.08
3976.89
4046.03
4083.23
3974.12
4096.29
4030.34
4105.8
4081.67
4004.17
4028.35
4012.85
4092.49
4033.65
4011.46
4121.13
4128.9
4075.18
4021.83
4156.59
4088.68
4080.46
4115.61
4056.16
4108.52
4058.98
4092.88
4112.45
4119.3
4095.48
4191.37
4136.43
4185.32
4113.29
4136.16
4155.35
4152.08
4151.1
4138.13
4131.85
4069.56
4235.91
4136.25
4106.42
4053.7
4072.79
4176.93
4193.62
4110.7
4147.17
4123.97
4143.11
4158.12
4148.6
4024.39
4136.56
4178.14
4136.51
4231.66
4223.31
4188.88
4086.52
4215.26
4206.6
4180.26
4252.21
4244.31
4185.03
4243.02
4197.51
4263.67
4267.57
4275.75
4231.28
4162.03
4256.81
4263.29
4129.87
4289.81
4123.36
4200.94
4242.08
4229.95
4285.49
4272.35
4197.35
4279.83
4237.02
4301.35
4352.33
4193.22
4209.17
4233.56
4263.41
4307.49
4379.98
4258.79
4269.86
4331.24
4263.18
4270.4
4276.06
4240.59
4277.29
4275.25
4203.47
4305
4285.82
4196.35
4368.3
4481.47
4246.35
4157.18
4328.6
4410.35
4376.15
4354.55
4335.81
4392.16
4340.92
4343.02
4271.41
4283.35
4254.59
4270.35
4240.52
4372.37
4323.97
4242.45
4352.45
4274.15
4297.12
4321.78
4325.54
4355.29
4452.66
4375.18
4296.08
4262.63
4300.74
4237.69
4283.69
4326.66
4281.31
4273.68
4330.48
4389.78
4332.93
4348.65
4288.65
4345.06
4370.31
4397.72
4362.82
4345.42
4364.34
4357.22
4327.87
4353.37
4451.95
4332.16
4429.95
4339.95
4216.31
4263.31
4320.16
4330.51
4308.67
4447.96
4494.01
4385.56
4277.58
4356.54
4352.84
4411.56
4353.25
4395.58
4319.95
4374.36
4402.94
4379.3
4375.09
4368.14
4333.94
4390.81
4351.79
4357.54
4449.37
4386.73
4452.23
4355.84
4350.64
4361.24
4381.32
4352.52
4461.08
4437.8
4439.35
4417.85
4492.85
4515.68
4406.36
4453.68
4393.75
4356.67
4391.73
4339.91
4345.86
4366.32
4430.27
4400.67
4397.58
4419.32
4420.78
4441.55
4397.89
4392.55
4402.68
4381.01
4428.97
4402.28
4359.72
4362.48
4434.94
4452.95
4450.41
4354.76
4469.43
4426.44
4389.26
4541.55
4467.45
4407.71
4432.6
4542.14
4479.26
4506.44
4393.51
4360.83
4453.86
4440.15
4580.36
4439.66
4488.4
4597.58
4485.68
4445.86
4496.7
4491.66
4514.24
4477.98
4512.23
4566.64
4502.55
4436.4
4589.31
4545.26
4556.21
4597.46
4571.29
4498.1
4507.92
4536.92
4592.05
4595.37
4595.78
4676.9
4724.35
4596.98
4521.19
4554.57
4553.71
4527.68
4490.75
4561.85
4521.66
4619.87
4503.16
4568.1
4702.22
4618.72
4552.51
4600.87
4631.76
4629.87
4584.64
4652.36
4640.38
4615.73
4582.6
4582.51
4632.2
4622.36
4619.47
4638.31
4748.84
4691.38
4710.94
4660.94
4621.16
4689.97
4713.14
4636.52
4616.72
4663.06
4631.37
4572.59
4741.49
4775.88
4753.88
4670.09
4754.41
4699.8
4699.77
4679.67
4670.96
4651.35
4718.07
4670.2
4667.12
4644.82
4671.36
4643.65
4770.85
4820.03
4658.46
4650.4
4734.14
4709.01
4779.39
4745.15
4683.91
4756.23
4750.9
4800.43
4867.75
4750.85
4787.54
4751.93
4765.51
4800.77
4819.13
4808.85
4806.16
4746.93
4772.88
4789.69
4751.23
4799.51
5001.74
4878.67
4740.99
4830.95
4876.72
4827.75
4776.84
4894.89
4887.78
4889.82
4881.6
4850.12
4879.95
4741.37
4820.03
4866.72
4818.07
4825.38
4974.17
4827.13
4868.45
4769.2
4880.32
4852.27
4846.03
5005.72
4834.92
4860.95
4839.08
4869.55
4892.08
4920.99
4872.56
4901.52
4786.22
4753.92
4802.28
4752.1
4794.81
4841.3
4817.44
4792.71
4810.97
4850.97
4827.32
4854.63
4730.93
4851.18
4786.12
4825.66
4891.95
4784.64
4746.03
4796.13
4843.4
4755.2
4716.41
4728.77
4823.41
4837.87
4866.65
4782.53
4740.02
4856.88
4815.23
4912.26
4859.78
4942.34
4949.21
4850.35
4795.33
4874.39
4980.52
4871.98
4887.53
4911.17
4894.36
4794.84
4888.17
4871.86
4804.57
4853.56
4793.56
4733.13
4822.91
4868.95
4871.11
4824.56
4795.18
4784.95
4751.47
4880
4868.15
4900.94
4876.43
4885.43
4794.05
4892.97
4909.75
4972.96
4823.97
4747.05
4902.87
4918.67
4919.62
4823.1
4900.81
4914.55
4885.38
4802.17
4827.96
4853.11
4878.97
4868.31
4891.3
4870.96
4895.99
4949.89
4912.29
4919.46
4904.34
4881.43
4911.16
4935.76
4864.56
4946.4
4987.74
4947.09
4891.29
4826.45
4987.07
4930.63
4950.33
5052.23
4979.57
4870.64
4923.64
4884.67
4983.42
4937.02
4866.66
4998.69
5111.39
5094.78
5053.63
5067.15
5104.96
4933.69
4928.74
5026.94
5030.4
5056.29
4906.88
4948.66
5037.53
5043.23
5009.83
5125.69
5031.99
5090.91
5005.31
5042.51
5019.54
5033.68
5076.52
5154.2
5106.72
5131.73
5160.34
5080.38
5050.83
5227.53
5290.6
5200.52
5214.32
5173.88
5183.68
5230.43
5138.01
5290.46
5253.95
5390.08
5356.65
5329.64
5292.16
5376.94
5335.27
5245.66
5368.81
5441.6
5401.84
5434.11
5438.11
5560.53
5570.09
5541.14
5605.74
5549.13
5679.4
5683.3
5738.5
5828.41
5811.46
5700.04
5725.8
5785
5794.56
5832.79
5934.43
6106.07
6081.69
6096.85
6104.29
6203.72
6170.28
6311.83
6373.05
6334.49
6450.86
6542.73
6551.33
6590.34
6600.22
6773.05
6927.12
6956.74
6994.89
7070.42
7201.56
7252.82
7147.65
7333.09
7471.27
7559.66
7561.16
7655.58
7764.69
7751.04
7885.76
7990.67
7962.08
8163.78
8127.56
8283.75
8248.97
8202.83
8258.21
8374.79
8452.89
8462.34
8388.54
8405.68
8260.62
8380.65
8223.47
8153.15
8130.2
8118.42
7981.23
8027.82
7842.57
7685.85
7501.67
7337.86
7260.22
7055.19
6889.48
6792.42
6672.4
6448.92
6299.44
6132.18
5920.46
5912.27
5706.68
5551.72
5478.24
5239.88
5223.45
5152.74
5013.78
4869.12
4811.66
4675.68
4550.82
4588.3
4455.67
4446.84
4230.36
4309.67
4235.88
4273.6
4176.62
4096.98
4000.45
4002.26
4064.12
4048.34
4066.72
3853.09
3946.12
3957.58
3820.74
3830.26
3936.32
3937.73
3836.12
3862.17
3894.7
3852.99
3800.09
3765.58
3761.08
3832.99
3849.86
3780.71
3853.95
3811.24
3781.76
3712.36
3768.18
3696.54
3792.84
3800.35
3829.45
3697.62
3744.48
3765.27
3767.43
3737.64
3701.87
3741.48
3729.32
3746.84
3743.21
3695.51
3813.21
3801.14
3785.62
3805.96
3841.97
3779.99
3705.56
3759.76
3719.57
3737.49
3789.12
3754.75
3715.24
3756.93
3843.47
3883.56
3806.79
3780.23
3839.91
3790.41
3867.42
3802.15
3749.96
3754.24
3846.29
3793.48
3829.05
3796.28
3885.43
3848.13
3867.07
3800.35
3773.67
3865.89
3829.67
3892.57
3879.52
3854.28
3915.31
3848.09
3793.74
3815.35
3913.6
3978.56
4033.62
3885.62
3827.84
3860.14
3881.52
3959.05
4008.95
3982.2
3885.02
3948.83
4009.47
3931.01
3965.53
4052.23
4020.04
3970.67
4055.53
3989.76
4121.71
4074.42
4005.57
4044.57
4065.28
4016.69
4012.54
4119.3
4119.76
4020.92
4163.17
4155.26
4042.82
4075.53
4127.9
4156.07
4224.74
4218.61
4166.98
4201.35
4139.07
4180.15
4211.06
4252.63
4344.78
4300.1
4298.05
4276.52
4316.61
4329.39
4372.63
4419.53
4360.47
4323.26
4338.61
4404.13
4376.29
4514.06
4413.64
4479.77
4497.92
4515.86
4543.77
4634.24
4660.76
4684.42
4660.43
4701.08
4681.27
4706.17
4702.44
4813.23
4800.26
4806.51
4862.51
4877.27
4993.94
5010.61
4960.56
5105.49
5288.63
5173.85
5012.86
5291.11
5283.42
5358.87
5388.48
5406.53
5455.44
5607.62
5653.33
5670.94
5748.85
5806.13
5948.11
6145.35
6164.73
6284.49
6306.28
6340.45
6565.44
6765.17
6913.01
7062.57
7245.37
7411.95
7642.8
7704.83
7825.08
8068.57
8349.87
8330.71
8648.5
8856
9077.44
9319.55
9584.33
9826.82
9994.38
10179
10410.5
10608.9
10979.8
11102.8
11329.3
11275.6
11405
11750.8
11896.7
12164.8
12086.3
12118.1
12094.7
12129.7
12198
12138.4
11975.7
11943.9
11584.3
11262.4
11007.3
10725.4
10361.3
10155.7
9769.61
9425.06
8748.74
8376.21
8036.79
7480.07
6940.43
6403.11
5932.53
5486.22
5011.19
4598.66
4124.51
3716.29
3357.85
3057.71
2782.81
2426.99
2236.87
1992.75
1838.01
1665.79
1540.29
1392.68
1284.73
1229.72
1141.69
1087.96
1077.3
1023.99
942.312
916.642
912.915
863.288
864.872
863.153
801.255
788.744
775.177
748.595
716.249
726.431
661.219
680.977
690.728
704.952
679.026
654.02
650.696
639.78
628.354
629.832
607.358
586.736
600.221
613.738
571.875
584.294
588.663
558.338
576.092
575.344
555.796
579.685
561.965
543.131
565.275
540.477
540.523
511.394
507.943
510.797
531.396
506.747
500.654
484.637
494.371
513.679
495.615
516.545
494.953
486.466
496.325
497.363
470.903
470.873
488.116
462.824
512.929
499.617
496.041
492.894
498.627
485.37
486.967
498.157
512.49
457.097
450.906
498.573
433.977
451.211
425.484
445.034
480.969
450.412
482.814
462.416
430.66
433.118
443.421
450.344
440.469
437.678
456.469
468.217
450.58
443.886
417.664
428.591
451.809
457.525
458.776
422.709
448.979
430.608
409.974
425.144
415.868
437.313
421.374
402.226
386.354
414.465
386.669
431.056
447.802
431.678
435.618
405.814
385.76
374.273
423.118
415.936
405.304
417.792
401.707
420.521
399.733
410.609
409.33
398.499
401.747
396.199
393.261
387.517
422.15
423.696
412.625
416.056
407.746
383.66
413.158
408.412
417.107
430.836
422.687
407.399
381.116
427.594
417.476
416.935
416.423
394.949
409.478
387.769
406.395
417.906
383.797
389.792
420.85
401.382
407.164
390.066
384.757
382.953
367.134
400.012
399.852
413.778
387.002
413.043
436.576
386.918
404.528
382.453
378.647
378.179
361.361
372.993
396.646
408.518
409.442
401.989
403.955
401.378
408.998
360.719
369.077
387.126
398.412
406.05
382.513
397.564
425.95
383.804
417.86
424.875
405.082
387.278
382.15
407.225
377.746
386.353
397.249
391.751
423.528
406.623
400.034
417.317
401.711
389.892
385.03
373.393
378.395
380.846
390.539
359.235
359.459
409.476
416.619
419.48
385.191
426.695
403.145
365.92
385.749
404.806
2.67321
Fe3s
Fe metal
2019
10
11
1
46
51
0
16
Casa Info Follows
0
0
0
0
File = C:/Users/pielsticker/Lukas/MPI-CEC/Projects/Ammonia Synthesis/Data/NAP-XPS/EX232_CEC427_Fe2O3_labREF.sle
Group = 33 Ramp down in H2, #Treatments:, #Temp: 600 C , #Pressure: 0.5 mbar, #Gas1: H2, #Gas2:, #Gas Ratio:, #Comments:
First of group = 0
Analyzer lens = AngleResolvedMode22:1.5kV
Analyzer slit = 4:7x20c\C:mesh
Scan mode = FixedAnalyzerTransmission
Kinetic energy start = 1384.61
c:\users\pielsticker\lukas\mpi-cec\projects\ammonia synthesis\data\nap-xps\raw data\ex232_cec427_fe2o3_labref.vms
C:\Users\pielsticker\SIALab\Project data\Ammonia Synthesis\Data\NAP-XPS\analyzed data\Iron references\Fe metal.vms
C:\Users\pielsticker\Lukas\MPI-CEC\Projects\Ammonia Synthesis\Data\NAP-XPS\analyzed data\Iron references\Fe_metal.vms
C:\Users\pielsticker\Lukas\MPI-CEC\Projects\Ammonia Synthesis\Data\NAP-XPS\analyzed data\Iron references\Iron_references.vms
XPS
0
Al
1486.61
0
0
0
54.5
180
FAT
20
1
4.3058
0
0
0
0
0
Fe
3s
-1
kinetic energy
eV
1384.61
0.05
2
counts
d
Transmission
d
pulse counting
0.2
1
0
0
0
0
2
ESCAPE DEPTH TYPE
d
1
MFP Exponent
d
0
722
216.529
489.839
2.00715
2.02019
294.067
2.02019
280.606
2.02016
292.385
2.02012
284.198
2.02008
267.108
2.02005
290.422
2.02001
296.231
2.01997
307.656
2.01994
288.165
2.0199
298.113
2.01986
288.243
2.01983
279.247
2.01979
280.22
2.01975
286.255
2.01972
281.255
2.01968
286.947
2.01965
267.533
2.01961
278.768
2.01957
289.98
2.01954
274.084
2.0195
259.779
2.01946
266.787
2.01943
286.119
2.01939
282.922
2.01935
269.147
2.01932
286.061
2.01928
268.84
2.01924
285.423
2.01921
275.683
2.01917
286.438
2.01913
288.873
2.0191
293.603
2.01906
295.532
2.01902
290.108
2.01899
293.023
2.01895
286.102
2.01891
303.195
2.01888
303.43
2.01884
280.391
2.0188
296.95
2.01877
285.752
2.01873
272.494
2.0187
267.718
2.01866
290.063
2.01862
287.654
2.01859
287.965
2.01855
321.668
2.01851
274.777
2.01848
313.867
2.01844
310.7
2.0184
303.678
2.01837
296.079
2.01833
300.626
2.01829
296.834
2.01826
288.102
2.01822
288.051
2.01818
296.036
2.01815
286.802
2.01811
288.955
2.01807
278.398
2.01804
309.553
2.018
322.275
2.01797
310.542
2.01793
290.704
2.01789
325.782
2.01786
303.875
2.01782
299.391
2.01778
291.173
2.01775
287.596
2.01771
292.777
2.01767
305.621
2.01764
287.068
2.0176
292.094
2.01756
290.87
2.01753
309.399
2.01749
289.998
2.01746
305.193
2.01742
322.137
2.01738
335.036
2.01735
303.615
2.01731
285.574
2.01727
282.597
2.01724
304.753
2.0172
297.237
2.01716
321.825
2.01713
309.942
2.01709
325.273
2.01705
294.973
2.01702
305.674
2.01698
304.963
2.01695
311.974
2.01691
314.856
2.01687
312.778
2.01684
282.301
2.0168
304.014
2.01676
317.691
2.01673
312.939
2.01669
293.337
2.01665
315.294
2.01662
323.733
2.01658
313.364
2.01654
308.914
2.01651
333.919
2.01647
322.29
2.01644
305.195
2.0164
321.43
2.01636
330.147
2.01633
318.026
2.01629
340.354
2.01625
323.715
2.01622
330.022
2.01618
331.573
2.01614
342.121
2.01611
302.867
2.01607
319.588
2.01604
326.141
2.016
350.978
2.01596
330.287
2.01593
343.588
2.01589
345.953
2.01585
333.72
2.01582
331.376
2.01578
340.013
2.01574
314.842
2.01571
352.332
2.01567
368.41
2.01564
328.168
2.0156
323.537
2.01556
355.159
2.01553
356.896
2.01549
341.82
2.01545
346.297
2.01542
322.981
2.01538
358.598
2.01534
358.662
2.01531
340.405
2.01527
352.26
2.01524
326.142
2.0152
329.672
2.01516
352.653
2.01513
373.85
2.01509
348.127
2.01505
328.898
2.01502
333.919
2.01498
346.442
2.01495
311.189
2.01491
348.276
2.01487
337.677
2.01484
355.438
2.0148
346.618
2.01476
350.612
2.01473
343.728
2.01469
344.566
2.01466
360.931
2.01462
358.877
2.01458
357.833
2.01455
375.292
2.01451
361.196
2.01447
345.039
2.01444
347.071
2.0144
331.656
2.01436
352.522
2.01433
350.127
2.01429
357.285
2.01426
359.203
2.01422
368.224
2.01418
370.663
2.01415
369.799
2.01411
340.125
2.01407
369.645
2.01404
370.988
2.014
330.284
2.01397
320.441
2.01393
338.257
2.01389
361.154
2.01386
371.075
2.01382
364.285
2.01378
363.975
2.01375
384.683
2.01371
367.845
2.01368
372.383
2.01364
374.372
2.0136
352.019
2.01357
381.608
2.01353
365.72
2.01349
397.569
2.01346
369.139
2.01342
396.376
2.01339
414.399
2.01335
359.916
2.01331
380.262
2.01328
384.001
2.01324
425.587
2.01321
415.581
2.01317
387.621
2.01313
413.947
2.0131
418.552
2.01306
409.862
2.01302
431.374
2.01299
435.308
2.01295
412.207
2.01292
442.96
2.01288
429.263
2.01284
439.031
2.01281
444.676
2.01277
453.17
2.01273
433.498
2.0127
433.913
2.01266
431.548
2.01263
454.306
2.01259
489.839
2.01255
457.631
2.01252
463.586
2.01248
452.433
2.01245
458.171
2.01241
470.85
2.01237
449.938
2.01234
480.67
2.0123
454.62
2.01226
458.251
2.01223
476.347
2.01219
435.784
2.01216
444.438
2.01212
434.874
2.01208
422.537
2.01205
453.105
2.01201
440.638
2.01198
439.429
2.01194
430.591
2.0119
424.95
2.01187
420.549
2.01183
427.479
2.01179
445.961
2.01176
419.398
2.01172
413.803
2.01169
414.703
2.01165
423.321
2.01161
376.988
2.01158
409.844
2.01154
408.597
2.01151
379.604
2.01147
376.696
2.01143
384.837
2.0114
362.418
2.01136
353.712
2.01132
360.811
2.01129
363.68
2.01125
356.806
2.01122
332.984
2.01118
324.848
2.01114
337.91
2.01111
322.02
2.01107
308.169
2.01104
294.297
2.011
311.998
2.01096
307.904
2.01093
299.471
2.01089
293.881
2.01086
290.572
2.01082
283.929
2.01078
269.473
2.01075
296.371
2.01071
303.258
2.01068
295.028
2.01064
295.445
2.0106
278.948
2.01057
258.279
2.01053
285.774
2.01049
299.324
2.01046
282.725
2.01042
263.591
2.01039
253.969
2.01035
269.721
2.01031
279.257
2.01028
263.737
2.01024
282.861
2.01021
295.383
2.01017
279.531
2.01013
283.138
2.0101
264.151
2.01006
240.336
2.01003
264.537
2.00999
277.415
2.00995
252.238
2.00992
255.7
2.00988
264.058
2.00985
257.783
2.00981
238.291
2.00977
241.318
2.00974
273.558
2.0097
266.901
2.00967
277.013
2.00963
278.991
2.00959
274.667
2.00956
270.302
2.00952
242.717
2.00949
231.411
2.00945
225.302
2.00941
218.607
2.00938
230.459
2.00934
242.773
2.00931
245.382
2.00927
242.128
2.00923
251.314
2.0092
237.063
2.00916
270.961
2.00913
247.609
2.00909
244.489
2.00905
262.392
2.00902
236.06
2.00898
240.409
2.00895
254.141
2.00891
244.32
2.00887
260.962
2.00884
273.448
2.0088
270.566
2.00877
239.688
2.00873
257.001
2.00869
241.602
2.00866
250.172
2.00862
232.443
2.00859
232.988
2.00855
228.322
2.00851
252.46
2.00848
251.903
2.00844
256.539
2.00841
258.231
2.00837
232.707
2.00833
243.751
2.0083
262.718
2.00826
247.49
2.00823
226.655
2.00819
242.394
2.00815
228.293
2.00812
254.35
2.00808
242.824
2.00805
235.072
2.00801
245.173
2.00797
267.906
2.00794
216.529
2.0079
239.102
2.00787
253.126
2.00783
263.376
2.0078
259.458
2.00776
265.471
2.00772
260.201
2.00769
228.859
2.00765
228.877
2.00762
235.754
2.00758
239.988
2.00754
248.767
2.00751
245.113
2.00747
234.872
2.00744
232.253
2.0074
243.87
2.00736
244.987
2.00733
260.805
2.00729
264.389
2.00726
245.956
2.00722
244.798
2.00718
248.953
2.00715
Fe3p
Fe metal
2019
10
11
2
2
7
0
16
Casa Info Follows
0
0
0
0
File = C:/Users/pielsticker/Lukas/MPI-CEC/Projects/Ammonia Synthesis/Data/NAP-XPS/EX232_CEC427_Fe2O3_labREF.sle
Group = 33 Ramp down in H2, #Treatments:, #Temp: 600 C , #Pressure: 0.5 mbar, #Gas1: H2, #Gas2:, #Gas Ratio:, #Comments:
First of group = 0
Analyzer lens = AngleResolvedMode22:1.5kV
Analyzer slit = 4:7x20c\C:mesh
Scan mode = FixedAnalyzerTransmission
Kinetic energy start = 1425.61
c:\users\pielsticker\lukas\mpi-cec\projects\ammonia synthesis\data\nap-xps\raw data\ex232_cec427_fe2o3_labref.vms
C:\Users\pielsticker\SIALab\Project data\Ammonia Synthesis\Data\NAP-XPS\analyzed data\Iron references\Fe metal.vms
C:\Users\pielsticker\Lukas\MPI-CEC\Projects\Ammonia Synthesis\Data\NAP-XPS\analyzed data\Iron references\Fe_metal.vms
C:\Users\pielsticker\Lukas\MPI-CEC\Projects\Ammonia Synthesis\Data\NAP-XPS\analyzed data\Iron references\Iron_references.vms
XPS
0
Al
1486.61
0
0
0
54.5
180
FAT
20
1
4.3058
0
0
0
0
0
Fe
3p
-1
kinetic energy
eV
1425.61
0.05
2
counts
d
Transmission
d
pulse counting
0.2
1
0
0
0
0
2
ESCAPE DEPTH TYPE
d
1
MFP Exponent
d
0
642
23.9903
879.468
1.97973
1.99084
235.335
1.99084
266.503
1.99081
261.949
1.99077
249.967
1.99074
230.792
1.9907
252.799
1.99067
252.646
1.99063
241.654
1.9906
229.08
1.99056
253.91
1.99053
241.53
1.99049
224.514
1.99046
245.432
1.99042
247.708
1.99039
279.732
1.99035
270.179
1.99032
248.477
1.99028
231.161
1.99025
260.623
1.99021
244.55
1.99018
241.422
1.99014
266.262
1.99011
258.736
1.99007
236.874
1.99004
239.004
1.99
244.893
1.98997
267.403
1.98993
265.904
1.9899
262.166
1.98986
258.219
1.98983
243.047
1.98979
256.168
1.98976
277.413
1.98972
259.838
1.98969
248.709
1.98965
266.226
1.98962
269.939
1.98958
270.297
1.98955
253.833
1.98951
248.917
1.98948
247.739
1.98944
231.84
1.98941
240.983
1.98937
252.105
1.98934
238.691
1.9893
238.819
1.98927
252.568
1.98923
268.117
1.9892
266.57
1.98916
260.215
1.98913
263.968
1.98909
266.828
1.98906
245.809
1.98902
245.872
1.98899
250.415
1.98895
243.203
1.98892
275.597
1.98888
267.393
1.98885
222.377
1.98881
252.604
1.98878
279.617
1.98874
259.118
1.98871
240.307
1.98868
252.866
1.98864
253.115
1.98861
279.379
1.98857
270.421
1.98854
284.967
1.9885
278.405
1.98847
254.443
1.98843
276.633
1.9884
277.344
1.98836
267.099
1.98833
259.878
1.98829
284.637
1.98826
279.303
1.98822
285.228
1.98819
257.515
1.98815
260.549
1.98812
283.082
1.98808
283.698
1.98805
278.014
1.98801
275.214
1.98798
299.033
1.98794
299.837
1.98791
294.674
1.98787
328.932
1.98784
288.393
1.9878
298.946
1.98777
284.744
1.98773
298.713
1.9877
292.476
1.98766
293.849
1.98763
303.744
1.98759
329.189
1.98756
301.842
1.98752
311.683
1.98749
310.17
1.98745
361.221
1.98742
326
1.98738
340.77
1.98735
364.64
1.98732
377.781
1.98728
334.634
1.98725
328.328
1.98721
334.696
1.98718
352.106
1.98714
352.649
1.98711
360.677
1.98707
360.13
1.98704
387.483
1.987
366.042
1.98697
398.59
1.98693
399.996
1.9869
382.124
1.98686
381.734
1.98683
369.256
1.98679
382.804
1.98676
413.261
1.98672
409.679
1.98669
431.806
1.98665
404.121
1.98662
426.693
1.98658
411.896
1.98655
469.047
1.98651
431.432
1.98648
443.01
1.98644
465.478
1.98641
495.457
1.98638
508.501
1.98634
500.865
1.98631
491.156
1.98627
509.265
1.98624
521.674
1.9862
543.48
1.98617
560.639
1.98613
547.903
1.9861
513.607
1.98606
540.794
1.98603
586.626
1.98599
588.876
1.98596
597.472
1.98592
625.509
1.98589
591.218
1.98585
632.987
1.98582
647.08
1.98578
655.831
1.98575
650.588
1.98571
684.91
1.98568
723.014
1.98565
751.185
1.98561
746.215
1.98558
718.544
1.98554
749.715
1.98551
795.648
1.98547
767.927
1.98544
805.05
1.9854
781.077
1.98537
760.79
1.98533
863.589
1.9853
855.893
1.98526
835.757
1.98523
879.468
1.98519
849.662
1.98516
785.816
1.98512
849.787
1.98509
844.996
1.98505
785.725
1.98502
841.328
1.98499
822.517
1.98495
792.773
1.98492
778.932
1.98488
790.51
1.98485
757.458
1.98481
753.049
1.98478
705.386
1.98474
698.385
1.98471
703.516
1.98467
662.354
1.98464
642.201
1.9846
636.225
1.98457
607.287
1.98453
573.227
1.9845
502.089
1.98447
493.547
1.98443
484.481
1.9844
413.681
1.98436
414.365
1.98433
388.068
1.98429
354.14
1.98426
312.22
1.98422
305.285
1.98419
296.825
1.98415
267.903
1.98412
244.748
1.98408
223.839
1.98405
230.806
1.98401
200.729
1.98398
169.217
1.98395
161.041
1.98391
157.062
1.98388
143.354
1.98384
138.849
1.98381
135.092
1.98377
108.834
1.98374
112.612
1.9837
82.1751
1.98367
100.693
1.98363
97.0859
1.9836
92.0832
1.98356
79.0634
1.98353
90.2747
1.98349
81.7909
1.98346
76.6384
1.98343
80.0757
1.98339
91.2292
1.98336
65.8263
1.98332
70.2833
1.98329
90.621
1.98325
74.476
1.98322
70.0728
1.98318
71.6285
1.98315
59.6481
1.98311
66.0923
1.98308
53.789
1.98304
69.2675
1.98301
69.8307
1.98298
58.3176
1.98294
45.5162
1.98291
62.7394
1.98287
60.0178
1.98284
58.0923
1.9828
53.0982
1.98277
47.7464
1.98273
46.3476
1.9827
51.365
1.98266
54.4536
1.98263
52.144
1.98259
52.1886
1.98256
46.8455
1.98253
45.1068
1.98249
42.4865
1.98246
38.1378
1.98242
44.9234
1.98239
38.4003
1.98235
50.3467
1.98232
57.0524
1.98228
53.9357
1.98225
48.9091
1.98221
42.4336
1.98218
45.4116
1.98215
50.391
1.98211
47.1393
1.98208
46.2816
1.98204
42.3867
1.98201
47.3884
1.98197
47.4299
1.98194
38.6194
1.9819
45.0077
1.98187
41.7168
1.98183
35.8145
1.9818
40.9653
1.98177
41.9546
1.98173
42.3923
1.9817
38.1964
1.98166
39.5649
1.98163
42.1412
1.98159
41.0361
1.98156
45.6285
1.98152
47.1134
1.98149
43.7377
1.98145
47.1763
1.98142
44.343
1.98139
39.2923
1.98135
37.5032
1.98132
31.7955
1.98128
41.8481
1.98125
43.0668
1.98121
43.4002
1.98118
44.6556
1.98114
43.0718
1.98111
41.7136
1.98107
39.6164
1.98104
36.6044
1.98101
40.4761
1.98097
39.6812
1.98094
41.0419
1.9809
35.6101
1.98087
35.8904
1.98083
37.1262
1.9808
39.9089
1.98076
40.0476
1.98073
38.2239
1.9807
36.1184
1.98066
32.5207
1.98063
34.5143
1.98059
36.126
1.98056
46.1266
1.98052
33.4236
1.98049
42.6118
1.98045
42.1525
1.98042
39.6786
1.98039
24.8874
1.98035
23.9903
1.98032
34.9901
1.98028
45.6575
1.98025
33.5599
1.98021
38.6565
1.98018
40.2329
1.98014
46.9429
1.98011
38.3377
1.98008
35.3557
1.98004
48.2713
1.98001
48.7855
1.97997
37.1168
1.97994
28.4233
1.9799
34.4857
1.97987
35.9035
1.97983
35.8644
1.9798
39.7325
1.97977
42.188
1.97973
Fe LMM
Fe metal
2019
10
11
2
4
47
0
16
Casa Info Follows
0
0
0
0
File = C:/Users/pielsticker/Lukas/MPI-CEC/Projects/Ammonia Synthesis/Data/NAP-XPS/EX232_CEC427_Fe2O3_labREF.sle
Group = 33 Ramp down in H2, #Treatments:, #Temp: 600 C , #Pressure: 0.5 mbar, #Gas1: H2, #Gas2:, #Gas Ratio:, #Comments:
First of group = 0
Analyzer lens = AngleResolvedMode22:1.5kV
Analyzer slit = 4:7x20c\C:mesh
Scan mode = FixedAnalyzerTransmission
Kinetic energy start = 686.61
c:\users\pielsticker\lukas\mpi-cec\projects\ammonia synthesis\data\nap-xps\raw data\ex232_cec427_fe2o3_labref.vms
C:\Users\pielsticker\SIALab\Project data\Ammonia Synthesis\Data\NAP-XPS\analyzed data\Iron references\Fe metal.vms
C:\Users\pielsticker\Lukas\MPI-CEC\Projects\Ammonia Synthesis\Data\NAP-XPS\analyzed data\Iron references\Fe_metal.vms
C:\Users\pielsticker\Lukas\MPI-CEC\Projects\Ammonia Synthesis\Data\NAP-XPS\analyzed data\Iron references\Iron_references.vms
XPS
0
Al
1486.61
0
0
0
54.5
180
FAT
20
1
4.3058
0
0
0
0
0
Fe LMM

-1
kinetic energy
eV
686.61
0.05
2
counts
d
Transmission
d
pulse counting
0.2
1
0
0
0
0
2
ESCAPE DEPTH TYPE
d
1
MFP Exponent
d
0
1242
1197.35
2003.58
2.81024
2.87337
1406.04
2.87337
1369.83
2.87326
1337.79
2.87316
1361.42
2.87305
1354.13
2.87295
1331.35
2.87284
1350.16
2.87274
1350.86
2.87263
1366.63
2.87253
1355.05
2.87242
1348.27
2.87232
1298.01
2.87221
1335.44
2.87211
1350.49
2.872
1368.47
2.8719
1337.06
2.87179
1324.7
2.87169
1341.54
2.87158
1349.43
2.87148
1338.27
2.87137
1348.71
2.87127
1371.01
2.87116
1384.79
2.87106
1375.29
2.87095
1359.21
2.87085
1321.78
2.87074
1332.31
2.87064
1370.35
2.87053
1343.71
2.87043
1339.87
2.87032
1371.46
2.87022
1386.02
2.87011
1334.15
2.87001
1332.49
2.8699
1362.79
2.8698
1347.52
2.86969
1312.84
2.86959
1380.79
2.86948
1301.29
2.86938
1382.89
2.86927
1374.4
2.86917
1334.15
2.86906
1387.98
2.86896
1352.33
2.86885
1378.29
2.86875
1384.25
2.86864
1336.88
2.86854
1327.71
2.86843
1299.95
2.86833
1323.64
2.86822
1380.97
2.86812
1389.96
2.86801
1377.6
2.86791
1343.66
2.86781
1367.14
2.8677
1310.09
2.8676
1333.87
2.86749
1314.15
2.86739
1335.03
2.86728
1319.53
2.86718
1402.78
2.86707
1418.12
2.86697
1366.89
2.86686
1364.69
2.86676
1328.08
2.86665
1374.53
2.86655
1377.33
2.86645
1398.4
2.86634
1396.5
2.86624
1367.42
2.86613
1401.4
2.86603
1335.09
2.86592
1348.35
2.86582
1404.58
2.86571
1394.93
2.86561
1389.04
2.86551
1358.8
2.8654
1394.2
2.8653
1371.74
2.86519
1359.02
2.86509
1379.67
2.86498
1359.04
2.86488
1298.15
2.86477
1337.78
2.86467
1411.83
2.86457
1385.82
2.86446
1433.58
2.86436
1333.78
2.86425
1337.17
2.86415
1341.92
2.86404
1350.17
2.86394
1389.45
2.86384
1383.55
2.86373
1382.94
2.86363
1344.14
2.86352
1366.22
2.86342
1358.71
2.86332
1317.69
2.86321
1398.77
2.86311
1364.96
2.863
1440.3
2.8629
1385.52
2.86279
1369.92
2.86269
1360.9
2.86259
1310.33
2.86248
1408.36
2.86238
1422.54
2.86227
1375.25
2.86217
1395.35
2.86207
1409.01
2.86196
1374.78
2.86186
1371.87
2.86175
1360.52
2.86165
1381.17
2.86155
1378.22
2.86144
1319.99
2.86134
1357.38
2.86123
1292.74
2.86113
1361.25
2.86103
1365.17
2.86092
1363.21
2.86082
1381.54
2.86071
1356.77
2.86061
1387.48
2.86051
1407.13
2.8604
1376.54
2.8603
1392.67
2.86019
1394.82
2.86009
1399.2
2.85999
1355.72
2.85988
1333.55
2.85978
1354.66
2.85968
1425.72
2.85957
1407.41
2.85947
1361.91
2.85936
1379.75
2.85926
1389.31
2.85916
1389.31
2.85905
1402.32
2.85895
1452.01
2.85885
1382.21
2.85874
1404.05
2.85864
1448.66
2.85853
1436.23
2.85843
1403.35
2.85833
1386.59
2.85822
1356.39
2.85812
1336.69
2.85802
1436.15
2.85791
1452.93
2.85781
1425.97
2.85771
1372.67
2.8576
1324.75
2.8575
1384.89
2.8574
1376.13
2.85729
1408.57
2.85719
1343.05
2.85708
1384.38
2.85698
1437.08
2.85688
1402.38
2.85677
1372.86
2.85667
1381.46
2.85657
1417.13
2.85646
1419.88
2.85636
1430.43
2.85626
1407.53
2.85615
1386.96
2.85605
1366.6
2.85595
1356.85
2.85584
1408.77
2.85574
1412.04
2.85564
1414.16
2.85553
1392.4
2.85543
1416.27
2.85533
1408.34
2.85522
1424.68
2.85512
1445.17
2.85502
1433.49
2.85491
1397.33
2.85481
1411.78
2.85471
1415.01
2.8546
1406.23
2.8545
1422.5
2.8544
1413.12
2.85429
1419.16
2.85419
1489.48
2.85409
1452.96
2.85398
1460.9
2.85388
1416.45
2.85378
1444.6
2.85368
1466.25
2.85357
1451.46
2.85347
1417.73
2.85337
1369.69
2.85326
1404.94
2.85316
1413.34
2.85306
1471.62
2.85295
1495.11
2.85285
1447.42
2.85275
1493.97
2.85264
1468.53
2.85254
1462.45
2.85244
1419.33
2.85234
1490.88
2.85223
1551.05
2.85213
1440.28
2.85203
1403.75
2.85192
1434.88
2.85182
1512.67
2.85172
1514.91
2.85161
1461.52
2.85151
1480.57
2.85141
1474.64
2.85131
1442.05
2.8512
1466.73
2.8511
1491.6
2.851
1428.79
2.85089
1468.42
2.85079
1477.34
2.85069
1454.56
2.85059
1463.86
2.85048
1475.71
2.85038
1507.32
2.85028
1486.03
2.85018
1499
2.85007
1530.07
2.84997
1506.24
2.84987
1517.7
2.84976
1460.59
2.84966
1486.49
2.84956
1515.62
2.84946
1538.91
2.84935
1470.37
2.84925
1510.16
2.84915
1520.59
2.84905
1479.99
2.84894
1525.85
2.84884
1520.78
2.84874
1495.02
2.84864
1538.6
2.84853
1567.82
2.84843
1497.07
2.84833
1544.72
2.84822
1532.85
2.84812
1468.89
2.84802
1503.08
2.84792
1579.66
2.84781
1566.2
2.84771
1579.14
2.84761
1544.65
2.84751
1505.73
2.8474
1551.27
2.8473
1598.21
2.8472
1564.3
2.8471
1544.45
2.847
1559.56
2.84689
1517.82
2.84679
1595.05
2.84669
1634.83
2.84659
1619.73
2.84648
1597.8
2.84638
1591.91
2.84628
1613.31
2.84618
1581.36
2.84607
1554.83
2.84597
1558.45
2.84587
1655.97
2.84577
1565.57
2.84566
1590.73
2.84556
1595.31
2.84546
1603.26
2.84536
1670.54
2.84526
1610.35
2.84515
1642.35
2.84505
1652.08
2.84495
1678.67
2.84485
1655.05
2.84474
1671.75
2.84464
1652.57
2.84454
1710.74
2.84444
1706.66
2.84434
1700.16
2.84423
1692.88
2.84413
1671.21
2.84403
1658.47
2.84393
1717.7
2.84383
1711.95
2.84372
1693.92
2.84362
1737.24
2.84352
1721.16
2.84342
1708.59
2.84332
1735.02
2.84321
1754.68
2.84311
1782.39
2.84301
1811.66
2.84291
1780.46
2.84281
1747.04
2.8427
1833.42
2.8426
1796.94
2.8425
1792.65
2.8424
1800.27
2.8423
1816.36
2.84219
1806.48
2.84209
1824.81
2.84199
1804.58
2.84189
1836.12
2.84179
1776.89
2.84168
1877.66
2.84158
1860.6
2.84148
1872.62
2.84138
1838.9
2.84128
1911.84
2.84118
1842.06
2.84107
1859.72
2.84097
1858.28
2.84087
1881.38
2.84077
1880.98
2.84067
1935.44
2.84057
1894.64
2.84046
1838.57
2.84036
1862.85
2.84026
1886.13
2.84016
1903.03
2.84006
1894.44
2.83996
1970.76
2.83985
1910.48
2.83975
1943.4
2.83965
1976.96
2.83955
1912.24
2.83945
[...]
0
Fe
2p
-1
kinetic energy
eV
736.61
0.05
2
counts
d
Transmission
d
pulse counting
1
1
0
0
0
0
2
ESCAPE DEPTH TYPE
d
0
MFP Exponent
d
0
1209.44
1
5803.56
5829.12
5828.88
5952.57
5960.12
6018.88
6026.78
5712.73
5627.13
5881.43
5968.69
6015.2
5949.83
5825.62
6022.39
6064.17
6135.95
5943.3
6023.29
6021.91
5996.43
6022.41
6062.93
6025.88
6037.29
6076.34
6163.13
5950.35
5837.37
6101.35
6073.11
6149.74
5874.7
5842.24
5913.78
6102.38
5949.74
5995.22
5882.37
6089.72
6188.2
5981.63
6161.15
6059.95
5799.31
5882.93
5959.35
5896.78
5963.82
6147.11
6072.26
6239.04
6060.67
6121.51
6035.55
5961.35
6092.65
6046.16
6051.25
5986.16
5938.03
5830.05
6016.54
6151.58
6149.34
6008.7
6001.62
6013.65
6030.82
6080.89
6037.61
6123.79
6178.59
6159.74
6149.26
6055.84
5960.02
6045.35
5964.03
6086.52
6163.67
6203.34
6224.74
6180.01
6169.18
5956.52
6054.8
6183.89
6186.74
6222.29
6051.31
6059.63
6123.01
5957.53
6014.57
6109.86
6059.68
6073.92
6088.53
6228.89
6134.07
5972.69
6056.18
6096.27
6332.54
6196.24
6234.12
6155.87
6082.73
6098.06
6207.14
6146.72
6156.82
6240.32
6261.17
6243.38
6151.14
6193.71
6197.85
6321.91
6107.5
6283.83
6324.05
6335.79
6083.43
6115.18
6070.32
6236.54
6164.66
6339.3
6232.25
6287.18
6175.81
6092.53
6160.47
6217.58
6227.76
6098.6
6074.31
6156.95
6147.82
6171.5
6026.7
6135.6
5904.29
6046.08
6301.49
6157.1
6065.62
6109.21
6138.83
6059.28
6122.98
5935.95
5883.62
6045.4
6158.08
6037.6
6144.44
6087.27
6213.27
6247.11
6239.17
6088.9
6070.31
5977.97
5996.25
6185.84
6180.06
6162.06
6115.22
6009.43
6210.76
6206.19
6101.03
6183.56
6143.06
6029.9
6080.02
5992.96
6270.28
5927.46
6068.89
6180.23
6145.39
6134.87
6163.8
6009.07
6117.84
6188.23
6111.79
6141.92
5868.77
6046.36
6199.58
6237.2
6051.12
6001.9
5968.28
6042.99
6035.14
5906.04
5916.91
6087.93
5876.8
6012.23
6007.36
6025.79
6021.66
5906.56
6090.06
6230.45
6134.7
6153.93
6093.6
6102.92
6101.53
5986.76
6062.64
6155.56
6111.91
6088.17
6042.09
6066.4
5910.57
5979.24
6060.58
6258.11
6214.3
6121.26
6189.67
6278.21
6222.19
6342.39
6055.66
6042
6024.76
6001.3
6056.94
6086.07
6146.32
6098.75
6081.34
6080.41
6087.41
6006.63
6186.42
6047.52
6096.94
6027.62
6097.35
6111.05
6180.8
6260.54
6269.15
6291.15
6315.94
6199.88
6195.87
6256.07
6227.6
6195.38
6400.61
6212.56
6123.19
6275.98
6391.14
6298.36
6341.4
6346.76
6449.01
6502.36
6178.88
6362.63
6381.12
6267.29
6354.67
6397.29
6437.45
6346.9
6391.78
6432.56
6388.95
6124.43
6426.22
6438.33
6278.19
6396.99
6446.62
6359.53
6354.77
6513.56
6441.93
6398.39
6485.44
6419.06
6391.53
6442.93
6648.74
6315.29
6485.43
6476.63
6465.39
6489.31
6698.41
6578.57
6613.87
6608.67
6527.06
6635.14
6640.96
6666.65
6491.98
6595.81
6563.8
6552.25
6865.22
6822.84
6619.96
6751.17
6700.71
6759.44
6693.69
6732.14
6739.32
6826.56
6792.3
6662.24
6691.03
6780.48
6761.23
6720.41
6686.46
6750.26
6804.68
6879.15
6867.84
6848.15
6980.11
6790.02
6937.96
6881.35
6911.67
7018.04
7014.86
6958.24
7072.08
7107.79
7269.74
7033.69
6960.73
7013.13
7074.08
7024.25
7155.93
7207.02
7232.69
6962.57
7102.21
7177.76
7223.28
7159.67
7125.16
7280.32
7226.22
7204.97
7056.11
7124.6
7118.7
7151.79
7222.2
7097.46
7097.62
7168.61
7396.28
7327.16
7339.83
7288.72
7281.76
7469.02
7524.11
7662.05
7565.52
7487.05
7395.06
7361.83
7330.62
7552.84
7551.02
7388.66
7290.24
7618.38
7516.09
7448.39
7523.74
7462.68
7386.81
7329.39
7265.81
7601.67
7544.87
7391.05
7430.82
7545.18
7515.2
7517.35
7594.01
7710.47
7591.55
7611.99
7604.19
7732.11
7527.5
7590.14
7615.98
7564.74
7676.79
7612.91
7377.15
7578.61
7562.34
7650.21
7467.21
7530.82
7503.81
7584.39
7664.09
7529.92
7540.31
7565.19
7643.5
7702.49
7672.82
7638.66
7451.05
7750.62
7758.28
7714.15
7683.23
7656.08
7600.09
7629.18
7784.99
7837.07
7656.5
7630.55
7701.4
7712.81
7781.5
7956.43
7833.89
7704.82
7708.93
7721.36
7832.55
7710.07
7786.58
7681.72
7717.76
8017.09
7971.12
7730.33
7789.5
7816.75
8026.96
7910.1
7887.54
8018.77
8110.98
8028.71
8096.39
8126.9
8141.67
8199.34
8258.27
8190.84
7983.83
8374.38
8481.55
8332.06
8398.65
8338.05
8232.58
8356.96
8403.81
8782.18
8469.47
8453.57
8514.44
8510.86
8571.76
8392.85
8661.25
8494.63
8817.47
8725.61
8802.99
8735.82
8749.01
8768.16
8982.35
8941.4
9025.58
8946.3
8913.89
9020.91
9121.6
9112.33
9097.51
9215.6
9121.9
9341.76
9093.68
9116.88
9312.39
9184.15
9022.25
9066.15
9187.09
9202.7
9112.02
9125.67
9201.25
9415.24
9466.88
9264.35
9353.02
9291.18
9155
9234.36
9130.75
9215.99
9125.62
9067.33
8980.57
9103.52
9204.55
9258.23
9154.22
9014.95
9166.02
9033.11
9025.02
8966.53
8927.04
8902.78
8988.08
8876.43
8992
8631.66
8912.86
8897.99
8816.69
8750.99
8735.42
8707.55
8588.97
8675.52
8563.02
8595.61
8558.46
8390
8387.32
8255.33
8264.39
8391.03
8107.58
8073.9
8282.97
8182.11
8062.89
8132.3
8059.93
7961.57
7891.23
7879.46
7857.31
7858.9
7881.43
7595.3
7590.54
7508.55
7646.2
7591.3
7607.05
7409.04
7461.36
7376.65
7349.46
7269.81
7290.67
7136.33
7140.69
7173.47
7102.01
7087.77
7061.71
6861.46
6913.29
6868.34
6933.81
6835.73
6859.5
6754.16
6980.13
6769.28
6784.9
6813.67
6795.87
6598.21
6607.44
6662.41
6612.36
6657.79
6733.82
6747.33
6676.17
6562.49
6599.39
6690.77
6611.74
6756.13
6713.11
6537.31
6600.57
6574.69
6640.83
6649.18
6608.73
6621.7
6623.51
6640.8
6636.54
6668.78
6624.83
6617.38
6407.42
6738.81
7049.74
6710.89
6637.43
6664.35
6705.15
6652.18
6708.39
6851.54
6875.62
6859
6777.96
6715.67
6775.78
6843.56
6821.99
6809.89
6768.85
6865.86
6759.67
6913.21
6913.26
6937.1
6989.4
7002.11
6835.64
6759.96
6965.12
7026.02
7007.72
6949.62
7012.53
6785.86
6784.93
6984.33
7115.69
7100.31
7077.14
6990.01
7047.67
7120.39
7044.81
7047.58
7180.05
7041.72
7315.66
7302.8
7115.73
7202.74
7216.66
7156.18
7251.35
7411.96
7370.44
7245.43
7431.11
7250.87
7320.64
7478.11
7548.9
7446.72
7471.49
7517
7526.47
7459.43
7414.04
7517.93
7477.49
7644.69
7686.23
7649.14
7510.7
7615.2
7854.42
7429.98
7735.51
7694.64
7762.35
7673.39
7682.22
7797.13
7767.02
7697.77
7672.94
7955.22
8019.01
7912.24
7883.82
7875.56
7880.64
8125.29
8207.15
8165
8125.44
8422.19
8326.59
8529.6
8410.68
8233.12
8347.74
8453.49
8515.6
8511.55
8406.66
8677.94
8808.92
8781.26
9047.1
8875.94
8916.18
8793.62
8615.29
8876.6
9008.49
8958.05
9100.6
9234.23
9269.26
9364.91
9300.59
9546.37
9508.26
9321.83
9706.18
9756.27
9525.93
9659.81
9994.66
10063.9
10125.3
9988.6
10047.6
9984.03
10122.3
10211.3
10133.2
10099.3
10256.5
10334.8
10410.6
10458.1
10506.6
10442.9
10465.4
10460.4
10523.4
10484.3
10453.8
10358.6
10381.2
10455
10615.3
10521.9
10500.1
10389.8
10358
10396.4
10493.9
10684.2
10525.4
10559
10273.7
10318.3
10387.2
10032.3
9915.61
10022
9865.47
9827.5
9812.44
9758.08
9729.39
9748.83
9604.14
9634.59
9643.58
9454.47
9167.96
9307.62
8984.67
8902.49
8858.58
8839.8
8557.45
8573.61
8474.77
8348.53
8326.61
8372.09
8161.43
8186.11
8044.37
8105.6
7856.03
7613.76
7465.62
7433.01
7489.79
7183.57
7059.52
7050.17
6875.91
6898.27
6771.64
6545.67
6577.34
6337.54
6217.55
6047.11
6030.65
5869.21
5783.23
5504.74
5527.35
5228.01
5127.03
4925.16
4945.76
4824.03
4597.15
4551.62
4422.64
4242.56
4139.96
4123.21
4042.92
3968.26
3835.55
3647.92
3596.44
3425.11
3390.88
3334.11
3265.98
3204.45
3140.21
3024.55
2870.16
2910.51
2828.69
2707.13
2636.58
2582.83
2597.51
2512.86
2497.18
2411.88
2350.03
2278.24
2274.6
2334.8
2228.09
2156.88
2159.76
2105.15
2070.2
2028.89
2029.42
1991.52
1867.69
1877.8
1888.33
1811.94
1853.47
1749.14
1738.37
1723.38
1636.27
1665.23
1616.72
1622.75
1575.67
1584.22
1524.09
1532.43
1551.03
1560.94
1536.63
1470.38
1470.8
1379.58
1446.9
1475.74
1383.84
1448.62
1469.52
1398.59
1335.51
1419.69
1344.57
1490.41
1492.08
1321.22
1459.75
1518.72
1464.12
1391.4
1385.58
1394.91
1442.07
1419.83
1427.85
1410.49
1432.47
1387.45
1325.23
1467.13
1349.86
1321.8
1346.57
1434.92
1350.37
1330.74
1344.91
1342.64
1283.64
1398.56
1337.29
1383.87
1279.72
1307.31
1353.64
1357.84
1348.12
1407.88
1416.69
1374.68
1354.42
1296.18
1338.64
1354.32
1338.36
1348.66
1332.28
1260.17
1343.92
1325.29
1241.12
1354.38
1291.34
1279.14
1299.56
1336.39
1364.35
1331.58
1298.7
1265.07
1359.26
1342.85
1362.79
1335.42
1340.59
1388.07
1347.98
1328.06
1323.93
1307.61
1383.12
1320.38
1310.69
1284.14
1294.98
1318.89
1300.58
1363.39
1387.37
1376.18
1354.41
1294.77
1358.81
1345.33
1391.12
1282.52
1298.14
1348.69
1361.94
1303.29
1321.85
1387.32
1339.61
1393.3
1299.63
1361.08
1301.75
1301.72
1344.5
1308.2
1268.09
1288.81
1252.89
1311.84
1298.42
1400.03
1300.76
1318.57
1386.69
1389.16
1355.41
1299.3
1316.69
1305.92
1430.95
1314.85
1389.57
1348.77
1336.33
1337.22
1233.91
1315.92
1342.52
1365.98
1325.11
1266.94
1247.49
1288.42
1409.02
1356.99
1293.08
1299.17
1296.57
1329.03
1311.19
1281.63
1241.51
1293.77
1279.66
1337.18
1295.75
1343.9
1343.62
1374.95
1314.56
1289.89
1309.93
1249.13
1300.02
1339.86
1337.62
1229.74
1284.32
1319.35
1326.32
1292.14
1389.18
1256.35
1297.33
1256.9
1371.68
1409.15
1272.72
1209.44
1308
1298.44
1267.14
1310.47
1276.54
1321.02
1340.06
1332.32
1358.48
1281.28
1243
1336.06
1358.23
1342.54
1266.5
1308.52
1281.87
1340.31
1346.32
1319.73
1324.3
1374.71
1269.87
1288.85
1261.21
1272.04
1332.2
1340.89
1382.52
1366.57
1335.21
1346.34
1302.58
1
Fe2p
Fe2O3 unscattered
2010
2020
12
16
27
56
0
14
Casa Info Follows
0
0
0
0
none
Group: none
Analyzer Lens: none
Analyzer Slit: none
Scan Mode: none
C:\Users\pielsticker\Lukas\MPI-CEC\Projects\Ammonia Synthesis\Data\NAP-XPS\analyzed data\Iron references\test2.vms
C:\Users\pielsticker\Lukas\MPI-CEC\Projects\Ammonia Synthesis\Data\NAP-XPS\analyzed data\Iron references\Iron_references.vms
CasaXP3
CasaXP3
XPS
0
Al
1486.61
0
0
0
56.5
180
FAT
0
1
0
0
0
0
0
0
Fe
2p
-1
kinetic energy
eV
726.61
0.05
2
counts
d
Transmission
d
pulse counting
1
1
0
0
0
0
2
ESCAPE DEPTH TYPE
d
0
MFP Exponent
d
0
1267.17
1
5002.41
5075.4
5036.74
5008.2
5020.76
4950.71
4972.51
4955.53
4982.62
5061.9
5005.26
5077.63
5110.71
5014.63
5055.92
4995.93
5014.99
5040.99
5066.1
5034.18
5011.8
5009.28
5026.37
5073.53
5012.5
5011.27
4995.42
5039.32
5006.58
4936.37
5000.73
5030.35
4992.16
4988.76
5043.58
5003.4
5036.62
5076.7
5031.95
5054.32
5045.88
5061.08
5045.38
5041.82
5030.89
5069.26
5063.91
5104.76
5073.19
5049.05
5080.38
5027.84
5110.03
5073.7
5127.71
5067.31
5102.01
5059.59
5065.08
5073.85
5055.55
5101.3
5086.51
5075.98
5100.5
5083.68
5030.72
5041.46
5019.7
5068.82
5087.95
5111.73
5155.2
5059.72
5052.62
5135.57
5051.35
5124.4
5095.41
5150.88
5069.33
5123.36
5145.67
5180.69
5140.37
5153.53
5090.94
5140.92
5171.78
5130.54
5124.28
5135.05
5100.77
5148
5182.42
5166.61
5164.58
5151.29
5117.35
5169.55
5146.87
5167.71
5140.49
5167.34
5146.11
5174.17
5199.99
5253.2
5143.17
5079.22
5175.5
5222.42
5213.73
5192.81
5124.83
5114.91
5183.65
5115.67
5134.66
5116.49
5218.07
5180.54
5154.58
5217.4
5169.57
5264.63
5181.49
5164.46
5177.07
5132.66
5211.61
5168.89
5204.53
5204.09
5190.05
5271.63
5212.63
5181.66
5196
5174.19
5186.16
5177.56
5179.26
5197.17
5235.2
5170.78
5163.53
5285.43
5208.63
5276.97
5195.21
5199.17
5300.09
5172.12
5189.97
5230.46
5223.19
5190.26
5177.45
5258.65
5197.97
5214.16
5240.39
5288.71
5273.27
5253.08
5261.36
5235.7
5281.43
5196.39
5189.83
5160.82
5207.12
5305.02
5255.63
5317.53
5210.23
5220.77
5298.67
5235.12
5314.81
5360.12
5298.58
5280.37
5277.98
5303.74
5231.48
5260.4
5290.02
5340.22
5279.75
5241.07
5202.65
5228.73
5269.37
5278.03
5274.8
5369.49
5355.71
5288.93
5249.38
5303.79
5262.37
5318.34
5287.01
5324.34
5332.79
5290.43
5304.59
5333.11
5284.93
5360.63
5370.88
5272.85
5352.04
5342.74
5285.39
5352.77
5302.9
5311.94
5307.1
5298.28
5291.64
5248.37
5291.49
5271.91
5393.05
5350.02
5419.35
5315.5
5341.62
5382.52
5345.82
5346.21
5332.64
5307.52
5357.19
5361.88
5319.52
5380.76
5369.88
5310.24
5373.42
5332.67
5383.92
5342.37
5396.36
5377.6
5360.54
5363.69
5401.07
5442.18
5403.74
5318.51
5420.97
5431.39
5378.98
5454.33
5381.46
5356.11
5416.01
5423.76
5445.31
5427.02
5405.1
5442.13
5337.07
5378.2
5471.44
5431.17
5401.13
5464.05
5423.31
5376.95
5343.03
5421.03
5424.72
5417.29
5376.55
5461.8
5494.34
5403.01
5448.15
5452.81
5383.32
5449.3
5401.15
5416.35
5449.17
5460.49
5424.8
5412.24
5493.75
5542.87
5465.79
5499.26
5518.7
5496.53
5473.17
5450.52
5465.32
5477.47
5486.48
5432.48
5482
5463.72
5502.28
5536.33
5507.6
5538.69
5538.69
5554.34
5549.79
5593.03
5561.52
5600.35
5624.01
5625.05
5547.1
5585.14
5737.31
5672.68
5686.42
5736.23
5668.68
5699.29
5662.39
5664.38
5746.22
5752.45
5776.31
5717.58
5679.06
5724.04
5783.77
5828.24
5862.12
5838.93
5898.55
5850.51
5855.77
5904.46
5899.34
5871.53
5843.4
5988.3
5942.92
5877.95
5898.27
5959.96
5924.36
6008.91
5939.18
5972.5
5959.95
6037.45
5938.81
5960.36
5925.04
5967.54
5932.23
5913.51
5901.51
5906.11
5890.87
5938.47
5998.85
5955.9
5967.46
5937.08
5971.6
5956.45
5961.37
5882.86
5905.67
5900.16
5974.3
5897.2
5968.22
5914.2
5932.68
5921.75
5906.95
5867.53
5924.19
5945.44
5877.63
5938.32
5928.05
5950.33
6004.02
5893.96
5856.46
5908.75
5866.37
5855.47
5820.18
5871.25
5894.85
5878.21
5897.71
5834.76
5795.78
5800.4
5825.13
5852.73
5877.56
5803.95
5802.11
5796.45
5824.85
5741.73
5739.1
5796.39
5741.75
5785.06
5775.58
5725.21
5757.74
5747.92
5773.86
5755.6
5766.9
5738.06
5766.19
5701.73
5786.68
5772.57
5775.21
5748.45
5750.58
5741
5720.16
5734.31
5813.52
5781.65
5783.09
5759.97
5855.7
5822.35
5721.41
5745.12
5746.37
5771.82
5794.9
5841.76
5880.21
5913.92
5820.65
5866.4
5758.8
5859.57
5866.01
5827.54
5886.08
5908.31
5938.66
5885.9
5873.87
5913.98
5928.44
5878.04
5909.54
5898.78
5967.04
5966.77
5992.75
6037.18
5991.18
6020.88
6023.79
5917.3
5943.82
6013.84
5999.9
5977.31
5991.86
6041.13
6081.07
6021.73
6071.92
6162.84
6037.77
6074.26
6106.91
6134.41
6109.57
6121.39
6049.69
6093.15
6196.5
6179.47
6216.44
6199.17
6213.32
6243.54
6298.85
6351.5
6298.39
6325.38
6271.7
6308.09
6366.19
6326.25
6296.79
6311.16
6338.63
6404.32
6398.97
6409.06
6337.39
6400.5
6359.51
6470.5
6495.27
6462.69
6465.88
6451.63
6412.85
6447.42
6508.68
6576.54
6534.23
6531.57
6663.57
6652.78
6672.35
6626.99
6571.51
6626.46
6653.53
6652.68
6735
6705.21
6775.69
6797.99
6701.88
6678.47
6727.72
6837.41
6764
6712.58
6747.52
6818.94
6867.86
6840.19
6883.68
6856.1
6829.73
6925.38
6926.32
6881.08
6891.87
6910.2
6851.95
6931.35
6998.86
6895.44
6912.09
6970.4
7007.08
6872.86
6927.83
6866.57
6935.66
6896.17
6898.6
6910.56
6879.65
6797.26
6832.57
6832.87
6830.3
6905.21
6933.03
6945.95
6854.02
6878.91
6847.93
6826.07
6837.4
6868.95
6892.36
6897.83
6854.89
6877.55
6808.07
6854.15
6844.42
6809.36
6788.61
6753.37
6841.85
6836.42
6728.66
6798.13
6833.81
6835.34
6773.45
6711.72
6814.5
6745.05
6773.67
6729.53
6767.71
6806.85
6809.8
6750.55
6770.23
6803.61
6764.98
6787.26
6802.48
6789.72
6774.56
6811.87
6777.05
6807.29
6794.17
6811.7
6890.4
6867.69
6830.71
6818.2
6951.56
6917.74
6818.89
6862.19
6929.63
6877.69
6964.87
6930.19
6908.1
6973.6
6984.59
6916.57
6968.07
7051.58
7017.72
7121.22
7075.2
7081.79
7068.46
7101.93
7105.2
7218.64
7184.79
7206.98
7262.9
7251.2
7247.23
7350.01
7330.48
7295.78
7315.95
7332.82
7310.55
7406.46
7391.6
7492.07
7440.25
7430.1
7598.25
7573.28
7576.57
7607.48
7671.27
7688.34
7719.6
7737.2
7852.68
7846.84
7874.1
7815.5
7891.85
7938.37
7972.33
8022.25
8003.69
8137.63
8125.16
8150.22
8142.91
8153.39
8185.54
8241.25
8297.27
8247.9
8289.12
8391.88
8454.21
8528.49
8488.25
8523.62
8461.25
8550.97
8606.69
8587.89
8671.62
8707.65
8737.53
8753.89
8780.21
8798.78
8832.06
8892.77
8942.63
8998.15
8959.32
9025.62
9064.01
9147.92
9211.26
9171.54
9240.48
9271.12
9285.44
9266.92
9263.47
9219.45
9218.48
9261.81
9254.26
9289.31
9251.56
9363.22
9350.14
9316.45
9289.81
9314.54
9320.27
9349.62
9284.9
9252.36
9263.2
9262.43
9076.28
9119.36
9098.97
9015.97
9023.45
8896.26
8882.38
8756.77
8814.53
8628.9
8536.34
8615.22
8551.4
8371.13
8295.64
8302.82
8256.19
8148.18
7953.98
7887.69
7832.2
7798.57
7694.2
7544.48
7535.63
7487.35
7370.48
7380.45
7239.89
7125.69
6963.45
6908.08
6860.84
6815.44
6756.52
6782.64
6726.01
6578.45
6631.16
6531.84
6544.74
6438.78
6536.15
6480.2
6389.44
6387.41
6426.59
6454.67
6363.71
6361.56
6382.38
6421.44
6391.17
6435.89
6335.78
6371.98
6358.61
6440.63
6412.27
6414.95
6441.33
6493.51
6524.01
6469.51
6490.73
6472.09
6519.61
6458.17
6553.83
6489.2
6553.26
6584.05
6536.64
6580
6517.17
6546.25
6635.3
6686.31
6644.02
6627.44
6677.24
6650.67
6677.85
6689.5
6696.88
6709.28
6683.47
6598.93
6738.2
6700.3
6709.23
6761.27
6678.57
6696.42
6779.73
6730.72
6702.44
6647.1
6723.16
6679.47
6688.8
6663.52
6653.4
6667.62
6626.1
6586.57
6590.39
6546.19
6550.37
6528.42
6496.35
6503.92
6546.86
6499.14
6432.67
6488.04
6388.03
6361.5
6374.91
6373.33
6316.35
6285.24
6331.85
6309.77
6242.88
6221.69
6242.18
6232.33
6124.24
6114.95
6104.72
6114.4
6108.89
6076.34
6019.25
6048.42
5982.06
6052.92
6032.75
5962.4
5900.22
5910.79
5926.35
5918.11
5862.21
5862.91
5865.64
5788.69
5788.42
5877.71
5833.9
5801.33
5853.14
5806.72
5805.82
5846.5
5803.26
5803.78
5775.68
5788.17
5801.55
5845.38
5875.76
5825.68
5816.99
5876.89
5902.42
5895.4
5795.91
5908.18
5895.09
5883.05
5913.07
5880.55
5963.99
5917.33
6013.16
6067.35
6070.06
6137.76
6154.59
6220.28
6206.78
6210.86
6280.94
6340.15
6282.09
6343.36
6400.2
6472.81
6498.1
6532.96
6557.62
6578.69
6613.32
6668.63
6707.17
6710.37
6734.21
6870.48
6929.55
7001.66
6960.01
7071.49
7130.45
7200.23
7298.34
7305.85
7361.81
7469.56
7475.85
7537.76
7608.01
7675.01
7666.86
7785.34
7769.69
7946.34
8064.68
8050.13
8089.58
8140.21
8269.18
8350.95
8343.12
8461.45
8534.83
8635.73
8714.35
8654.44
8820.42
8845.08
8914.22
9085.36
9112.32
9192.43
9262.86
9314.45
9504.21
9586.38
9636.94
9649.39
9745.85
9803.72
9893.99
9947.65
10009.2
10048.3
10177.6
10216.4
10209.8
10264.6
10322
10409.1
10411.6
10468.2
10443.3
10500.2
10585.1
10532.9
10550.6
10494.6
10417.6
10551.7
10425.8
10370.5
10325.8
10307.5
10260.4
10222.3
10077.4
9941.87
9852.14
9807.1
9661.67
9453.13
9357.16
9144.88
9067.56
8836.93
8628.72
8380.76
8283.75
7976.33
7655.54
7418.51
7165.2
6858.7
6590.24
6295.11
6011.62
5678.56
5325.67
5003.58
4770.43
4501.35
4208.95
3928.53
3661.65
3492.95
3278.01
3061.26
2850.54
2742.64
2554.74
2381.42
2261.21
2181
2043.86
2010.43
1986.13
1853.35
1850.72
1854.65
1789.34
1735.01
1722.6
1715.79
1697.53
1670.24
1623.09
1568.91
1604.14
1570.52
1593.48
1545.02
1514.28
1528.5
1561.3
1500.2
1476
1524.18
1510.9
1509.17
1467.33
1453.78
1473.28
1474.4
1455.61
1419.36
1453.38
1464.24
1440.3
1412.85
1441.47
1436.8
1433.99
1396.75
1389.37
1407.8
1413.7
1421.11
1424.06
1466.11
1412.19
1418.26
1382.88
1379
1403.87
1382.93
1379.68
1383.32
1425.14
1449.26
1358.98
1386.23
1399.83
1377.56
1361.79
1392.56
1372.22
1354.4
1363.75
1419.94
1384.14
1347.52
1362.47
1389.27
1357.67
1383.94
1361.57
1349.73
1341.46
1379.63
1313.03
1348.71
1383.99
1340.49
1334.52
1294.03
1354.09
1373.69
1367.62
1350.74
1362.76
1343.41
1369.48
1372.73
1341.1
1368.06
1361.09
1345.77
1303.82
1338.31
1332.23
1366.09
1322.25
1320.02
1358.77
1345
1363.42
1318.84
1334.01
1317.69
1331.7
1317.5
1313.02
1305.29
1366.96
1351.01
1335.85
1360.8
1326.71
1297.29
1274.7
1298.8
1324.93
1332.66
1326.82
1320.38
1306.84
1343.46
1324.14
1327.2
1314.96
1302.2
1327.93
1304.35
1317.89
1315.57
1294.59
1305.62
1343.02
1329.39
1332.64
1334.7
1385.37
1307.87
1320.2
1332.82
1310.4
1330.64
1302.83
1291.13
1287.44
1277.74
1283.57
1325.01
1306.26
1356.11
1343.63
1326.48
1315.51
1288.57
1298.91
1289.66
1322.55
1339.93
1345.22
1313.16
1325.91
1316.22
1339.87
1326.13
1301.77
1320.1
1292.16
1293.76
1311.3
1294.82
1314.23
1328.73
1315.6
1271.27
1303.57
1269.44
1299.07
1332.17
1322.77
1294.28
1290.59
1341.88
1347.5
1323.46
1308.76
1295.74
1319.46
1272.11
1289.79
1280.67
1285.35
1319.58
1312.91
1313.87
1325.53
1302.71
1297.97
1333.28
1336.3
1323.42
1290.71
1272.73
1355.17
1309.57
1289.82
1300.47
1302.79
1343.83
1330.8
1330.63
1318.19
1301.35
1270.13
1289.57
1332.6
1297.26
1312.19
1322.52
1299.65
1304.54
1298.79
1306.69
1322.36
1314.35
1267.17
1303.93
1312.29
1324.26
1324.81
1304.05
1329.16
1313.37
1272.16
1311.77
1328.43
1272.48
1329.28
1333.74
1321.63
1337.02
1295.26
1302.54
1285.57
1311.69
1299.34
1302.69
1316.97
1331.41
1323.55
1346.14
1309.41
1272.34
1281.43
1288.84
1279.14
1297.62
1319.73
1314.3
1303.44
1300.99
1324.22
1321.28
1300.3
1315.02
1337.82
1328.51
1301.54
1297.62
1295.81
1311.52
1330.1
1316.93
1323.34
1281.61
1312.08
1
end of experiment